['heart']
It is none
None
Starting meta-learning
Using dice
OUTER EPOCH 0
Dataset 11, hippocampus_anterior
Inner Epoch 0
Learning rate 0.010000
> /scratch2/mganesh/MetaMedSeg/MetaMedSeg/networks/unet.py(83)forward()
-> conv1 = self.dconv_down1(x)
(Pdb)
Traceback (most recent call last):
  File "experiment_runner.py", line 239, in <module>
    target_name=data.get("weights_name"))
  File "experiment_runner.py", line 51, in meta_train
    reptile.outer_loop(evaluate_every=4, path_to_save=save_path)
  File "/scratch2/mganesh/MetaMedSeg/MetaMedSeg/meta_learning/reptile.py", line 286, in outer_loop
    task_weights, loss_history, iou_history, task_val_loss, task_val_iou = self.inner_loop(dataset_id)
  File "/scratch2/mganesh/MetaMedSeg/MetaMedSeg/meta_learning/reptile.py", line 427, in inner_loop
    output, _ = model(image)
  File "/home1/mganesh/miniconda3/envs/medseg/lib/python3.7/site-packages/torch/nn/modules/module.py", line 1194, in _call_impl
    return forward_call(*input, **kwargs)
  File "/scratch2/mganesh/MetaMedSeg/MetaMedSeg/networks/unet.py", line 83, in forward
    conv1 = self.dconv_down1(x)
  File "/scratch2/mganesh/MetaMedSeg/MetaMedSeg/networks/unet.py", line 83, in forward
    conv1 = self.dconv_down1(x)
  File "/home1/mganesh/miniconda3/envs/medseg/lib/python3.7/bdb.py", line 88, in trace_dispatch
    return self.dispatch_line(frame)
  File "/home1/mganesh/miniconda3/envs/medseg/lib/python3.7/bdb.py", line 112, in dispatch_line
    self.user_line(frame)
  File "/home1/mganesh/miniconda3/envs/medseg/lib/python3.7/pdb.py", line 259, in user_line
    self.interaction(frame, None)
  File "/home1/mganesh/miniconda3/envs/medseg/lib/python3.7/pdb.py", line 350, in interaction
    self._cmdloop()
  File "/home1/mganesh/miniconda3/envs/medseg/lib/python3.7/pdb.py", line 319, in _cmdloop
    self.cmdloop()
  File "/home1/mganesh/miniconda3/envs/medseg/lib/python3.7/cmd.py", line 126, in cmdloop
    line = input(self.prompt)
OSError: [Errno 9] Bad file descriptor